//
//  error_message.cpp
//  integral
//
// MIT License
//
// Copyright (c) 2020 Andr√© Pereira Henriques (aphenriques (at) outlook (dot) com)
//
// Permission is hereby granted, free of charge, to any person obtaining a copy
// of this software and associated documentation files (the "Software"), to deal
// in the Software without restriction, including without limitation the rights
// to use, copy, modify, merge, publish, distribute, sublicense, and/or sell
// copies of the Software, and to permit persons to whom the Software is
// furnished to do so, subject to the following conditions:
//
// The above copyright notice and this permission notice shall be included in all
// copies or substantial portions of the Software.
//
// THE SOFTWARE IS PROVIDED "AS IS", WITHOUT WARRANTY OF ANY KIND, EXPRESS OR
// IMPLIED, INCLUDING BUT NOT LIMITED TO THE WARRANTIES OF MERCHANTABILITY,
// FITNESS FOR A PARTICULAR PURPOSE AND NONINFRINGEMENT. IN NO EVENT SHALL THE
// AUTHORS OR COPYRIGHT HOLDERS BE LIABLE FOR ANY CLAIM, DAMAGES OR OTHER
// LIABILITY, WHETHER IN AN ACTION OF CONTRACT, TORT OR OTHERWISE, ARISING FROM,
// OUT OF OR IN CONNECTION WITH THE SOFTWARE OR THE USE OR OTHER DEALINGS IN THE
// SOFTWARE.

#include <cstdlib>
#include <iostream>
#include <lua.hpp>
#include <stdexcept>
#include <integral/integral.hpp>

int main() {
    try {
        const integral::State luaState;
        luaState.openLibs();
        luaState["throwException"].setFunction(
            [] {
                throw std::runtime_error("exception!");
            }
        );
        try {
            luaState.doFile("sample.lua");
        } catch (const integral::StateException &stateException) {
            std::cout << "expected exception: {" << stateException.what() << "}\n";
        }
        try {
            luaState.doString("throwException()");
        } catch (const integral::StateException &stateException) {
            std::cout << "expected exception: {" << stateException.what() << "}\n";
        }
        return EXIT_SUCCESS;
    } catch (const std::exception &exception) {
        std::cerr << "[state] " << exception.what() << std::endl;
    } catch (...) {
        std::cerr << "unknown exception thrown" << std::endl;
    }
    return EXIT_FAILURE;
}
